<mujoco model='humanoid'>
    <compiler inertiafromgeom='true' settotalmass="130" angle='degree'/>

    <default>
        <joint limited='true' damping='1' armature='0'/>
        <geom contype='1' conaffinity='1' condim='1' rgba='0.8 0.6 .4 1'
        	margin="0.001" solref=".02 1" solimp=".8 .8 .01" material="geom"/>
        <motor ctrlrange='-1.0 1.0' ctrllimited='true'/>
        <default class="humanoid">
        </default>
    </default>

    <visual>
        <map fogstart="3" fogend="5" force="0.1" znear="0.5"/>
        <global offwidth="800" offheight="800"/> 
    </visual>

    <option integrator="RK4" iterations="50" solver="PGS" timestep="0.005"/>

    <size nstack="1000000"/>

    <asset>
	<texture type="skybox" builtin="gradient" width="128" height="128" rgb1=".4 .6 .8" rgb2="0 0 0"/>  
        <texture name="texgeom" type="cube" builtin="flat" mark="cross" width="127" height="1278" 
            rgb1="0.8 0.6 0.4" rgb2="0.8 0.6 0.4" markrgb="1 1 1" random="0.01"/>  
        <texture name="texplane" type="2d" builtin="checker" rgb1=".2 .3 .4" rgb2=".1 0.15 0.2" 
            width="512" height="512"/>  

        <material name='MatPlane' reflectance='0.3' texture="texplane" texrepeat="1 1" texuniform="true"/>
        <material name='geom' texture="texgeom" texuniform="true"/>
    </asset>

    <worldbody>
	
        <geom name='floor' pos='0 0 0' size='50 50 .125' type='plane' rgba="0.0 0.0 0.0 0.0" condim='3' friction="1 .1 .1"/>

	<camera name='targeting' pos='1 1 2' mode='targetbodycom' target='torso'/>

        <body name='torso' pos='0 0 1.4' childclass="humanoid">

	<camera name='tracking' pos='1 1 2' zaxis="1 2 3" mode='trackcom'/>

            <freejoint name="root"/>
            <geom name='torso1' type='capsule' fromto='0 -.07 0 0 .07 0'  size='0.07'/>
            <geom name='head' type='sphere' pos='0 0 0.19' size='0.09'/>
	    <site name="head" pos="0 0 0.19" size="0.10" type="sphere" rgba="0.3 0.2 0.1 0.3"/>
            <geom name='uwaist' type='capsule' fromto='-.01 -.06 -.12 -.01 .06 -.12' size='0.06'/>
            <body name='lwaist' pos='-.01 0 -0.260' quat='1.000 0 -0.002 0' >
                <geom name='lwaist' type='capsule' fromto='0 -.06 0 0 .06 0'  size='0.06' />
                <joint name='abdomen_z' type='hinge' pos='0 0 0.065' axis='0 0 1' range='-45 45' damping='5' stiffness='20' armature='0.02' />
                <joint name='abdomen_y' type='hinge' pos='0 0 0.065' axis='0 1 0' range='-75 30' damping='5' stiffness='10' armature='0.02' />
                <body name='pelvis' pos='0 0 -0.165' quat='1.000 0 -0.002 0' >
                    <joint name='abdomen_x' type='hinge' pos='0 0 0.1' axis='1 0 0' range='-35 35' damping='5' stiffness='10' armature='0.02' />
                    <geom name='butt' type='capsule' fromto='-.02 -.07 0 -.02 .07 0'  size='0.09' />
                    <body name='right_thigh' pos='0 -0.1 -0.04' >
                        <joint name='right_hip_x' type='hinge' pos='0 0 0' axis='1 0 0' range='-25 5'   damping='5' stiffness='10' armature='0.01' />
                        <joint name='right_hip_z' type='hinge' pos='0 0 0' axis='0 0 1' range='-60 35'  damping='5' stiffness='10' armature='0.01' />
                        <joint name='right_hip_y' type='hinge' pos='0 0 0' axis='0 1 0' range='-120 20' damping='5' stiffness='20' armature='0.01' />
                        <geom name='right_thigh1' type='capsule' fromto='0 0 0 0 0.01 -.34'  size='0.06' />
                        <body name='right_shin' pos='0 0.01 -0.403' >
                            <joint name='right_knee' type='hinge' pos='0 0 .02' axis='0 -1 0' range='-160 -2' stiffness='1' armature='0.0060' />
                            <geom name='right_shin1' type='capsule' fromto='0 0 0 0 0 -.3'   size='0.049' />
                            <body name='right_foot' pos='0 0 -.39' >
                                <joint name='right_ankle_y' type='hinge' pos='0 0 0.08' axis='0 1 0'   range='-50 50' stiffness='4' armature='0.0008' />
                                <joint name='right_ankle_x' type='hinge' pos='0 0 0.04' axis='1 0 0.5' range='-50 50' stiffness='1'  armature='0.0006' />
                                <geom name='right_foot_cap1' type='capsule' fromto='-.07 -0.02 0 0.14 -0.04 0'  size='0.027' />
                                <geom name='right_foot_cap2' type='capsule' fromto='-.07 0 0 0.14  0.02 0'  size='0.027' />
				<site name="rightfoot" pos="0.12 -0.01 -0.01" size=".05 .04 .03" type="box" rgba="0.3 0.2 0.1 0.3"/> 
				<site name="rightfootheel" pos="-0.05 -0.01 -0.01" size=".04 .03 .03" type="box" rgba="0.3 0.2 0.1 0.3"/>
                            </body>
                        </body>
                    </body>
                    <body name='left_thigh' pos='0 0.1 -0.04' >
                        <joint name='left_hip_x' type='hinge' pos='0 0 0' axis='-1 0 0' range='-25 5'  damping='5' stiffness='10' armature='0.01' />
                        <joint name='left_hip_z' type='hinge' pos='0 0 0' axis='0 0 -1' range='-60 35' damping='5' stiffness='10' armature='0.01' />
                        <joint name='left_hip_y' type='hinge' pos='0 0 0' axis='0 1 0' range='-120 20' damping='5' stiffness='20' armature='0.01' />
                        <geom name='left_thigh1' type='capsule' fromto='0 0 0 0 -0.01 -.34'  size='0.06' />
                        <body name='left_shin' pos='0 -0.01 -0.403' >
                            <joint name='left_knee' type='hinge' pos='0 0 .02' axis='0 -1 0' range='-160 -2' stiffness='1' armature='0.0060' />
                            <geom name='left_shin1' type='capsule' fromto='0 0 0 0 0 -.3'   size='0.049' />
                            <body name='left_foot' pos='0 0 -.39' >
                                <joint name='left_ankle_y' type='hinge' pos='0 0 0.08' axis='0 1 0'   range='-50 50'  stiffness='4' armature='0.0008' />
                                <joint name='left_ankle_x' type='hinge' pos='0 0 0.04' axis='1 0 0.5' range='-50 50'  stiffness='1'  armature='0.0006' />
                                <geom name='left_foot_cap1' type='capsule' fromto='-.07 0.02 0 0.14 0.04 0'  size='0.027' />
                                <geom name='left_foot_cap2' type='capsule' fromto='-.07 0 0 0.14  -0.02 0'  size='0.027' />
  				<site name="leftfoot" pos="0.12 0.01 -0.01" size=".05 .04 .03" type="box" rgba="0.3 0.2 0.1 0.3"/>
				<site name="leftfootheel" pos="-0.05 0.01 -0.01" size=".05 .03 .03" type="box" rgba="0.3 0.2 0.1 0.3"/>
                            </body>
                        </body>
                    </body>
                </body>
            </body>
            <body name='right_upper_arm' pos='0 -0.17 0.06' >
                <joint name='right_shoulder1' type='hinge' pos='0 0 0' axis='2 1 1'  range='-85 60' stiffness='1' armature='0.0068' />
                <joint name='right_shoulder2' type='hinge' pos='0 0 0' axis='0 -1 1' range='-85 60' stiffness='1'  armature='0.0051' />
                <geom name='right_uarm1' type='capsule' fromto='0 0 0 .16 -.16 -.16'  size='0.04 0.16' />
                <body name='right_lower_arm' pos='.18 -.18 -.18' >
                    <joint name='right_elbow' type='hinge' pos='0 0 0' axis='0 -1 1' range='-90 50'  stiffness='0' armature='0.0028' />
                    <geom name='right_larm' type='capsule' fromto='0.01 0.01 0.01 .17 .17 .17'  size='0.031' />
                    <geom name='right_hand' type='sphere' pos='.18 .18 .18'  size='0.04'/>
		    <site name="righthand"  pos='.18 .18 .18' size='.05 .05 .05' type="box" rgba="0.3 0.2 0.1 0.3"/>
                </body>
            </body>
            <body name='left_upper_arm' pos='0 0.17 0.06' >
                <joint name='left_shoulder1' type='hinge' pos='0 0 0' axis='2 -1 1' range='-60 85' stiffness='1' armature='0.0068' />
                <joint name='left_shoulder2' type='hinge' pos='0 0 0' axis='0 1 1' range='-60 85'  stiffness='1' armature='0.0051' />
                <geom name='left_uarm1' type='capsule' fromto='0 0 0 .16 .16 -.16'  size='0.04 0.16' />
                <body name='left_lower_arm' pos='.18 .18 -.18' >
                    <joint name='left_elbow' type='hinge' pos='0 0 0' axis='0 -1 -1' range='-90 50' stiffness='0' armature='0.0028' />
                    <geom name='left_larm' type='capsule' fromto='0.01 -0.01 0.01 .17 -.17 .17'  size='0.031' />
                    <geom name='left_hand' type='sphere' pos='.18 -.18 .18'  size='0.04'/>
		    <site name="lefthand"  pos='.18 -.18 .18' size='.05 .05 .05' type="box" rgba="0.3 0.2 0.1 0.3"/>
                </body>
            </body>
        </body>
    </worldbody>

    <tendon>
        <fixed name="left_hipknee">
            <joint coef="-1" joint="left_hip_y"/>
            <joint coef="1" joint="left_knee"/>
        </fixed>
        <fixed name="right_hipknee">
            <joint coef="-1" joint="right_hip_y"/>
            <joint coef="1" joint="right_knee"/>
        </fixed>
    </tendon>


    <sensor>
    	<touch name="rightfoottouch" site="rightfoot" />
	<touch name="leftfoottouch" site="leftfoot" />
	<touch name="rightfoottouch2" site="rightfootheel" />
	<touch name="leftfoottouch2" site="leftfootheel" />

	<touch name="righthandtouch" site="righthand" />
	<touch name="lefthandtouch" site="lefthand" />

	<accelerometer name="accHead" site="head" />
	<gyro name="gyroHead" site="head" />

	<tendonpos name="left_hipknee" tendon="left_hipknee" />
	<tendonpos name="right_hipknee" tendon="right_hipknee" />

	<tendonvel name="left_hipkneeV" tendon="left_hipknee" />
	<tendonvel name="right_hipkneeV" tendon="right_hipknee" />

	<jointpos name="abdomen_y"    		joint="abdomen_y" />
        <jointpos name="abdomen_z"    		joint="abdomen_z" />
        <jointpos name="abdomen_x"    		joint="abdomen_x" />

        <jointpos name="right_hip_x"  		joint="right_hip_x" />
        <jointpos name="right_hip_z"  		joint="right_hip_z" />
        <jointpos name="right_hip_y"  		joint="right_hip_y" />
        <jointpos name="right_knee"   		joint="right_knee" />
        <jointpos name="right_ankle_x"		joint="right_ankle_x" />
        <jointpos name="right_ankle_y"  	joint="right_ankle_y" />

        <jointpos name="left_hip_x"     	joint="left_hip_x" />
        <jointpos name="left_hip_z"     	joint="left_hip_z" />
        <jointpos name="left_hip_y"     	joint="left_hip_y" />
        <jointpos name="left_knee"      	joint="left_knee" />
        <jointpos name="left_ankle_x"   	joint="left_ankle_x" />
        <jointpos name="left_ankle_y"   	joint="left_ankle_y" />

        <jointpos name="right_shoulder1"	joint="right_shoulder1" />
        <jointpos name="right_shoulder2"	joint="right_shoulder2" />
        <jointpos name="right_elbow"    	joint="right_elbow" />

        <jointpos name="left_shoulder1"  	joint="left_shoulder1" />
        <jointpos name="left_shoulder2"  	joint="left_shoulder2" />
        <jointpos name="left_elbow"      	joint="left_elbow" />

	<jointvel name="vabdomen_y"    		joint="abdomen_y" />
        <jointvel name="vabdomen_z"    		joint="abdomen_z" />
        <jointvel name="vabdomen_x"    		joint="abdomen_x" />

        <jointvel name="vright_hip_x"  		joint="right_hip_x" />
        <jointvel name="vright_hip_z"  		joint="right_hip_z" />
        <jointvel name="vright_hip_y"  		joint="right_hip_y" />
        <jointvel name="vright_knee"   		joint="right_knee" />
        <jointvel name="vright_ankle_x"		joint="right_ankle_x" />
        <jointvel name="vright_ankle_y"  	joint="right_ankle_y" />

        <jointvel name="vleft_hip_x"     	joint="left_hip_x" />
        <jointvel name="vleft_hip_z"     	joint="left_hip_z" />
        <jointvel name="vleft_hip_y"     	joint="left_hip_y" />
        <jointvel name="vleft_knee"      	joint="left_knee" />
        <jointvel name="vleft_ankle_x"   	joint="left_ankle_x" />
        <jointvel name="vleft_ankle_y"   	joint="left_ankle_y" />

        <jointvel name="vright_shoulder1"	joint="right_shoulder1" />
        <jointvel name="vright_shoulder2"	joint="right_shoulder2" />
        <jointvel name="vright_elbow"    	joint="right_elbow" />

        <jointvel name="vleft_shoulder1"  	joint="left_shoulder1" />
        <jointvel name="vleft_shoulder2"  	joint="left_shoulder2" />
        <jointvel name="vleft_elbow"      	joint="left_elbow" />
    </sensor>


    <actuator>
        <motor gear="100" joint="abdomen_y" name="abdomen_y"/>
        <motor gear="100" joint="abdomen_z" name="abdomen_z"/>
        <motor gear="100" joint="abdomen_x" name="abdomen_x"/>

        <motor gear="100" joint="right_hip_x" name="right_hip_x"/>
        <motor gear="100" joint="right_hip_z" name="right_hip_z"/>
        <motor gear="300" joint="right_hip_y" name="right_hip_y"/>
        <motor gear="200" joint="right_knee" name="right_knee"/>
	<motor gear="150" name="right_ankle_x"   	joint="right_ankle_x" />
        <motor gear="50"  name="right_ankle_y"   	joint="right_ankle_y" />

        <motor gear="100" joint="left_hip_x" name="left_hip_x"/>
        <motor gear="100" joint="left_hip_z" name="left_hip_z"/>
        <motor gear="300" joint="left_hip_y" name="left_hip_y"/>
        <motor gear="200" joint="left_knee" name="left_knee"/>
	<motor gear="150" name="left_ankle_x"   	joint="left_ankle_x" />
        <motor gear="50"  name="left_ankle_y"   	joint="left_ankle_y" />

        <motor gear="25" joint="right_shoulder1" name="right_shoulder1"/>
        <motor gear="25" joint="right_shoulder2" name="right_shoulder2"/>
        <motor gear="25" joint="right_elbow" name="right_elbow"/>

        <motor gear="25" joint="left_shoulder1" name="left_shoulder1"/>
        <motor gear="25" joint="left_shoulder2" name="left_shoulder2"/>
        <motor gear="25" joint="left_elbow" name="left_elbow"/>
    </actuator>

</mujoco>
